Workbook

Sheet Predictions
A1: Date | B1: Div | C1: League | D1: Home | E1: Away | F1: League avg | G1: Model expects | H1: P(o1.5) | I1: P(o2.5) | J1: P(o3.5) | K1: P(o4.5) | L1: P(o5.5) | M1: P(o6.5) | N1: FAIR over 1.5 | O1: FAIR over 2.5 | P1: FAIR over 3.5 | Q1: FAIR over 4.5 | R1: FAIR over 5.5 | S1: FAIR over 6.5 | T1: FAIR under 1.5 | U1: FAIR under 2.5 | V1: FAIR under 3.5 | W1: FAIR under 4.5 | X1: FAIR under 5.5 | Y1: FAIR under 6.5 | Z1: P(0) | AA1: P(1) | AB1: P(2) | AC1: P(3) | AD1: P(4) | AE1: P(5) | AF1: P(6) | AG1: P(7) | AH1: P(8) | AI1: Referee used | AJ1: Ref x avg | AK1: Ref matches | AL1: ACTUAL yellows | AM1: Bookmaker | AN1: Card line | AO1: Over price | AP1: Under price | AQ1: Model P(over) | AR1: Model FAIR over | AS1: Model FAIR under | AT1: Implied P(over) | AU1: Edge | AV1: BET? | AW1: EV | AX1: Won? | AY1: P/L units | AZ1: Notes
A2: 2026-09-18 | B2: E0 | C2: Premier League | D2: Brentford | E2: Chelsea | F2: 3.9 | G2: 4.0068672 | H2: 0.89983377 | I2: 0.75103974 | J2: 0.55999911 | K2: 0.37234666 | L2: 0.22198689 | M2: 0.11965166 | N2: 1.1113164 | O2: 1.3314875 | P2: 1.7857171 | Q2: 2.6856693 | R2: 4.5047705 | S2: 8.3575939 | T2: 9.9834042 | U2: 4.0167053 | V2: 2.2727227 | W2: 1.5932362 | X2: 1.2853254 | Y2: 1.135914 | Z2: 0.02132456 | AA2: 0.078841673 | AB2: 0.14879403 | AC2: 0.19104063 | AD2: 0.18765245 | AE2: 0.15035977 | AF2: 0.10233523 | AG2: 0.060829419 | AH2: 0.032225686 | AI2: a madley | AJ2: 0.82051282 | AK2: 394 | AL2: 2 | AM2: screenshot | AN2: 3.5 | AO2: 1.5 | AP2: 2.34 | AQ2: =IFERROR(IF($AN2="","",INDEX($H2:$M2,$AN2-0.5)),"line must be 1.5-6.5") | AR2: =IF(ISNUMBER($AQ2),1/$AQ2,"") | AS2: =IF(ISNUMBER($AQ2),1/(1-$AQ2),"") | AT2: =IF($AO2="","",IF($AP2="",1/$AO2,(1/$AO2)/((1/$AO2)+(1/$AP2)))) | AU2: =IF(OR(NOT(ISNUMBER($AQ2)),$AT2=""),"",$AQ2-$AT2) | AV2: =IF($AU2="","",IF($AU2>=0.05,"OVER",IF($AU2<=-0.05,"UNDER","skip"))) | AW2: =IF($AV2="OVER",$AQ2*$AO2-1,IF($AV2="UNDER",IF($AP2="","need under price",(1-$AQ2)*$AP2-1),"")) | AX2: =IF(OR($AV2="",$AV2="skip",$AL2="",$AN2=""),"",IF($AV2="OVER",IF($AL2>$AN2,"WON","LOST"),IF($AL2<$AN2,"WON","LOST"))) | AY2: =IF($AX2="","",IF($AX2="WON",IF($AV2="OVER",$AO2-1,$AP2-1),-1)) | AZ2: also offered o4.5 2.14 / u4.5 1.60; actual from BBC 2026-09-18 (provisional, ~97% exact vs football-data)
A3: 2026-09-19 | B3: E0 | C3: Premier League | D3: Tottenham | E3: Aston Villa | F3: 3.9 | G3: 4.2526153 | H3: 0.91657158 | I3: 0.78415754 | J3: 0.60457178 | K3: 0.41823525 | L3: 0.26052023 | M3: 0.14713298 | N3: 1.0910223 | O3: 1.275254 | P3: 1.6540633 | Q3: 2.3909988 | R3: 3.8384735 | S3: 6.7965725 | T3: 11.986323 | U3: 4.6330087 | V3: 2.528904 | W3: 1.7189079 | X3: 1.352302 | Y3: 1.1725157 | Z3: 0.017007221 | AA3: 0.066421203 | AB3: 0.13241404 | AC3: 0.17958576 | AD3: 0.18633653 | AE3: 0.15771502 | AF3: 0.11338724 | AG3: 0.071195136 | AH3: 0.03984157 | AI3: s barrott | AJ3: 0.94871795 | AK3: 167 | AL3: 3 | AQ3: =IFERROR(IF($AN3="","",INDEX($H3:$M3,$AN3-0.5)),"line must be 1.5-6.5") | AR3: =IF(ISNUMBER($AQ3),1/$AQ3,"") | AS3: =IF(ISNUMBER($AQ3),1/(1-$AQ3),"") | AT3: =IF($AO3="","",IF($AP3="",1/$AO3,(1/$AO3)/((1/$AO3)+(1/$AP3)))) | AU3: =IF(OR(NOT(ISNUMBER($AQ3)),$AT3=""),"",$AQ3-$AT3) | AV3: =IF($AU3="","",IF($AU3>=0.05,"OVER",IF($AU3<=-0.05,"UNDER","skip"))) | AW3: =IF($AV3="OVER",$AQ3*$AO3-1,IF($AV3="UNDER",IF($AP3="","need under price",(1-$AQ3)*$AP3-1),"")) | AX3: =IF(OR($AV3="",$AV3="skip",$AL3="",$AN3=""),"",IF($AV3="OVER",IF($AL3>$AN3,"WON","LOST"),IF($AL3<$AN3,"WON","LOST"))) | AY3: =IF($AX3="","",IF($AX3="WON",IF($AV3="OVER",$AO3-1,$AP3-1),-1)) | AZ3: actual from BBC 2026-09-19 (provisional, ~97% exact vs football-data)
A4: 2026-09-19 | B4: E0 | C4: Premier League | D4: Brighton | E4: Arsenal | F4: 3.9 | G4: 4.1204293 | H4: 0.90793538 | I4: 0.76684354 | J4: 0.58096488 | K4: 0.39361848 | L4: 0.23958676 | M4: 0.1320168 | N4: 1.1014 | O4: 1.304047 | P4: 1.7212744 | Q4: 2.5405312 | R4: 4.1738533 | S4: 7.5747935 | T4: 10.861936 | U4: 4.2889654 | V4: 2.3864348 | W4: 1.6491268 | X4: 1.3150744 | Y4: 1.152096 | Z4: 0.019205331 | AA4: 0.072859284 | AB4: 0.14109185 | AC4: 0.18587865 | AD4: 0.18734641 | AE4: 0.15403171 | AF4: 0.10756996 | AG4: 0.065609521 | AH4: 0.035665041 | AI4: d england | AJ4: 1.1794872 | AK4: 280 | AL4: 5 | AQ4: =IFERROR(IF($AN4="","",INDEX($H4:$M4,$AN4-0.5)),"line must be 1.5-6.5") | AR4: =IF(ISNUMBER($AQ4),1/$AQ4,"") | AS4: =IF(ISNUMBER($AQ4),1/(1-$AQ4),"") | AT4: =IF($AO4="","",IF($AP4="",1/$AO4,(1/$AO4)/((1/$AO4)+(1/$AP4)))) | AU4: =IF(OR(NOT(ISNUMBER($AQ4)),$AT4=""),"",$AQ4-$AT4) | AV4: =IF($AU4="","",IF($AU4>=0.05,"OVER",IF($AU4<=-0.05,"UNDER","skip"))) | AW4: =IF($AV4="OVER",$AQ4*$AO4-1,IF($AV4="UNDER",IF($AP4="","need under price",(1-$AQ4)*$AP4-1),"")) | AX4: =IF(OR($AV4="",$AV4="skip",$AL4="",$AN4=""),"",IF($AV4="OVER",IF($AL4>$AN4,"WON","LOST"),IF($AL4<$AN4,"WON","LOST"))) | AY4: =IF($AX4="","",IF($AX4="WON",IF($AV4="OVER",$AO4-1,$AP4-1),-1)) | AZ4: actual from BBC 2026-09-19 (provisional, ~97% exact vs football-data)
A5: 2026-09-19 | B5: E0 | C5: Premier League | D5: Everton | E5: Ipswich | F5: 3.9 | G5: 4.5683201 | H5: 0.93414352 | I5: 0.82107271 | J5: 0.6573289 | K5: 0.47591628 | L5: 0.3119634 | M5: 0.18610371 | N5: 1.0704993 | O5: 1.2179189 | P5: 1.5213084 | Q5: 2.1012099 | R5: 3.2055042 | S5: 5.3733481 | T5: 15.184534 | U5: 5.5888623 | V5: 2.9182502 | W5: 1.9080921 | X5: 1.4534111 | Y5: 1.2286578 | Z5: 0.012737871 | AA5: 0.053118611 | AB5: 0.11307081 | AC5: 0.1637438 | AD5: 0.18141262 | AE5: 0.16395288 | AF5: 0.1258597 | AG5: 0.084381903 | AH5: 0.050421057 | AI5: s attwell | AJ5: 1.3076923 | AK5: 448 | AL5: 3 | AQ5: =IFERROR(IF($AN5="","",INDEX($H5:$M5,$AN5-0.5)),"line must be 1.5-6.5") | AR5: =IF(ISNUMBER($AQ5),1/$AQ5,"") | AS5: =IF(ISNUMBER($AQ5),1/(1-$AQ5),"") | AT5: =IF($AO5="","",IF($AP5="",1/$AO5,(1/$AO5)/((1/$AO5)+(1/$AP5)))) | AU5: =IF(OR(NOT(ISNUMBER($AQ5)),$AT5=""),"",$AQ5-$AT5) | AV5: =IF($AU5="","",IF($AU5>=0.05,"OVER",IF($AU5<=-0.05,"UNDER","skip"))) | AW5: =IF($AV5="OVER",$AQ5*$AO5-1,IF($AV5="UNDER",IF($AP5="","need under price",(1-$AQ5)*$AP5-1),"")) | AX5: =IF(OR($AV5="",$AV5="skip",$AL5="",$AN5=""),"",IF($AV5="OVER",IF($AL5>$AN5,"WON","LOST"),IF($AL5<$AN5,"WON","LOST"))) | AY5: =IF($AX5="","",IF($AX5="WON",IF($AV5="OVER",$AO5-1,$AP5-1),-1)) | AZ5: actual from BBC 2026-09-19 (provisional, ~97% exact vs football-data)
A6: 2026-09-19 | B6: E0 | C6: Premier League | D6: Newcastle | E6: Hull | F6: 3.9 | G6: 4.0386071 | H6: 0.90216462 | I6: 0.75554505 | J6: 0.56592116 | K6: 0.37829973 | L6: 0.22686666 | M6: 0.12304807 | N6: 1.1084451 | O6: 1.3235478 | P6: 1.7670306 | Q6: 2.6434066 | R6: 4.4078756 | S6: 8.1269053 | T6: 10.221252 | U6: 4.0907333 | V6: 2.303729 | W6: 1.6084921 | X6: 1.2934379 | Y6: 1.1403134 | Z6: 0.02070927 | AA6: 0.077126106 | AB6: 0.14661957 | AC6: 0.1896239 | AD6: 0.18762143 | AE6: 0.15143307 | AF6: 0.10381859 | AG6: 0.062161931 | AH6: 0.033172169 | AI6: t harrington | AJ6: 0.71794872 | AK6: 317 | AL6: 5 | AQ6: =IFERROR(IF($AN6="","",INDEX($H6:$M6,$AN6-0.5)),"line must be 1.5-6.5") | AR6: =IF(ISNUMBER($AQ6),1/$AQ6,"") | AS6: =IF(ISNUMBER($AQ6),1/(1-$AQ6),"") | AT6: =IF($AO6="","",IF($AP6="",1/$AO6,(1/$AO6)/((1/$AO6)+(1/$AP6)))) | AU6: =IF(OR(NOT(ISNUMBER($AQ6)),$AT6=""),"",$AQ6-$AT6) | AV6: =IF($AU6="","",IF($AU6>=0.05,"OVER",IF($AU6<=-0.05,"UNDER","skip"))) | AW6: =IF($AV6="OVER",$AQ6*$AO6-1,IF($AV6="UNDER",IF($AP6="","need under price",(1-$AQ6)*$AP6-1),"")) | AX6: =IF(OR($AV6="",$AV6="skip",$AL6="",$AN6=""),"",IF($AV6="OVER",IF($AL6>$AN6,"WON","LOST"),IF($AL6<$AN6,"WON","LOST"))) | AY6: =IF($AX6="","",IF($AX6="WON",IF($AV6="OVER",$AO6-1,$AP6-1),-1)) | AZ6: actual from BBC 2026-09-19 (provisional, ~97% exact vs football-data); corrected 2026-09-28 from 6 to 5: football-data (the source the model was trained on) says 1+4, cards confirmed, fouls agree 14/14
A7: 2026-09-19 | B7: E0 | C7: Premier League | D7: Nott'm Forest | E7: Coventry | F7: 3.9 | G7: 3.7688112 | H7: 0.88057603 | I7: 0.71499978 | J7: 0.51411999 | K7: 0.32766986 | L7: 0.18650125 | M7: 0.095713015 | N7: 1.1356203 | O7: 1.3986018 | P7: 1.9450712 | Q7: 3.0518523 | R7: 5.3618942 | S7: 10.4479 | T7: 8.3735284 | U7: 3.5087693 | V7: 2.0581213 | W7: 1.4873645 | X7: 1.2292582 | Y7: 1.1058436 | Z7: 0.026576432 | AA7: 0.092847538 | AB7: 0.16557625 | AC7: 0.20087979 | AD7: 0.18645014 | AE7: 0.1411686 | AF7: 0.09078824 | AG7: 0.050993647 | AH7: 0.025527163 | AI7: j gillett | AJ7: 1 | AK7: 164 | AL7: 2 | AQ7: =IFERROR(IF($AN7="","",INDEX($H7:$M7,$AN7-0.5)),"line must be 1.5-6.5") | AR7: =IF(ISNUMBER($AQ7),1/$AQ7,"") | AS7: =IF(ISNUMBER($AQ7),1/(1-$AQ7),"") | AT7: =IF($AO7="","",IF($AP7="",1/$AO7,(1/$AO7)/((1/$AO7)+(1/$AP7)))) | AU7: =IF(OR(NOT(ISNUMBER($AQ7)),$AT7=""),"",$AQ7-$AT7) | AV7: =IF($AU7="","",IF($AU7>=0.05,"OVER",IF($AU7<=-0.05,"UNDER","skip"))) | AW7: =IF($AV7="OVER",$AQ7*$AO7-1,IF($AV7="UNDER",IF($AP7="","need under price",(1-$AQ7)*$AP7-1),"")) | AX7: =IF(OR($AV7="",$AV7="skip",$AL7="",$AN7=""),"",IF($AV7="OVER",IF($AL7>$AN7,"WON","LOST"),IF($AL7<$AN7,"WON","LOST"))) | AY7: =IF($AX7="","",IF($AX7="WON",IF($AV7="OVER",$AO7-1,$AP7-1),-1)) | AZ7: actual from BBC 2026-09-19 (provisional, ~97% exact vs football-data)
A8: 2026-09-20 | B8: E0 | C8: Premier League | D8: Bournemouth | E8: Liverpool | F8: 3.9 | G8: 3.8627658 | H8: 0.88856515 | I8: 0.72970452 | J8: 0.53252644 | K8: 0.3452905 | L8: 0.20025687 | M8: 0.10483139 | N8: 1.1254099 | O8: 1.3704177 | P8: 1.877841 | Q8: 2.8961121 | R8: 4.9935866 | S8: 9.539128 | T8: 8.9738533 | U8: 3.6996549 | V8: 2.1391584 | W8: 1.527395 | X8: 1.2504015 | Y8: 1.117108 | Z8: 0.024361648 | AA8: 0.087073202 | AB8: 0.15886063 | AC8: 0.19717808 | AD8: 0.18723594 | AE8: 0.14503364 | AF8: 0.095425481 | AG8: 0.054834635 | AH8: 0.028083133 | AI8: m oliver | AJ8: 0.94871795 | AK8: 537 | AL8: 3 | AQ8: =IFERROR(IF($AN8="","",INDEX($H8:$M8,$AN8-0.5)),"line must be 1.5-6.5") | AR8: =IF(ISNUMBER($AQ8),1/$AQ8,"") | AS8: =IF(ISNUMBER($AQ8),1/(1-$AQ8),"") | AT8: =IF($AO8="","",IF($AP8="",1/$AO8,(1/$AO8)/((1/$AO8)+(1/$AP8)))) | AU8: =IF(OR(NOT(ISNUMBER($AQ8)),$AT8=""),"",$AQ8-$AT8) | AV8: =IF($AU8="","",IF($AU8>=0.05,"OVER",IF($AU8<=-0.05,"UNDER","skip"))) | AW8: =IF($AV8="OVER",$AQ8*$AO8-1,IF($AV8="UNDER",IF($AP8="","need under price",(1-$AQ8)*$AP8-1),"")) | AX8: =IF(OR($AV8="",$AV8="skip",$AL8="",$AN8=""),"",IF($AV8="OVER",IF($AL8>$AN8,"WON","LOST"),IF($AL8<$AN8,"WON","LOST"))) | AY8: =IF($AX8="","",IF($AX8="WON",IF($AV8="OVER",$AO8-1,$AP8-1),-1)) | AZ8: actual from BBC 2026-09-20 (provisional, ~97% exact vs football-data)
A9: 2026-09-20 | B9: E0 | C9: Premier League | D9: Leeds | E9: Crystal Palace | F9: 3.9 | G9: 3.3778241 | H9: 0.84111668 | I9: 0.64681715 | J9: 0.43393211 | K9: 0.25548612 | L9: 0.13346995 | M9: 0.062602954 | N9: 1.1888957 | O9: 1.546032 | P9: 2.304508 | Q9: 3.914107 | R9: 7.492323 | S9: 15.973687 | T9: 6.293927 | U9: 2.8313946 | V9: 1.7665726 | W9: 1.3431583 | X9: 1.1540281 | Y9: 1.0667838 | Z9: 0.038238428 | AA9: 0.12064489 | AB9: 0.19429953 | AC9: 0.21288504 | AD9: 0.17844599 | AE9: 0.12201617 | AF9: 0.070866999 | AG9: 0.035947252 | AH9: 0.016251272 | AI9: a herczeg | AJ9: 0.71794872 | AK9: 111 | AL9: 5 | AQ9: =IFERROR(IF($AN9="","",INDEX($H9:$M9,$AN9-0.5)),"line must be 1.5-6.5") | AR9: =IF(ISNUMBER($AQ9),1/$AQ9,"") | AS9: =IF(ISNUMBER($AQ9),1/(1-$AQ9),"") | AT9: =IF($AO9="","",IF($AP9="",1/$AO9,(1/$AO9)/((1/$AO9)+(1/$AP9)))) | AU9: =IF(OR(NOT(ISNUMBER($AQ9)),$AT9=""),"",$AQ9-$AT9) | AV9: =IF($AU9="","",IF($AU9>=0.05,"OVER",IF($AU9<=-0.05,"UNDER","skip"))) | AW9: =IF($AV9="OVER",$AQ9*$AO9-1,IF($AV9="UNDER",IF($AP9="","need under price",(1-$AQ9)*$AP9-1),"")) | AX9: =IF(OR($AV9="",$AV9="skip",$AL9="",$AN9=""),"",IF($AV9="OVER",IF($AL9>$AN9,"WON","LOST"),IF($AL9<$AN9,"WON","LOST"))) | AY9: =IF($AX9="","",IF($AX9="WON",IF($AV9="OVER",$AO9-1,$AP9-1),-1)) | AZ9: actual from BBC 2026-09-20 (provisional, ~97% exact vs football-data)
A10: 2026-09-20 | B10: E0 | C10: Premier League | D10: Man City | E10: Sunderland | F10: 3.9 | G10: 4.1948919 | H10: 0.91290106 | I10: 0.77673727 | J10: 0.59437051 | K10: 0.40750983 | L10: 0.25132489 | M10: 0.14043896 | N10: 1.095409 | O10: 1.2874366 | P10: 1.6824522 | Q10: 2.4539286 | R10: 3.9789135 | S10: 7.1205311 | T10: 11.481196 | U10: 4.4790278 | V10: 2.465304 | W10: 1.6877917 | X10: 1.3356929 | Y10: 1.1633845 | Z10: 0.017933649 | AA10: 0.069165289 | AB10: 0.13616379 | AC10: 0.18236675 | AD10: 0.18686069 | AE10: 0.15618494 | AF10: 0.11088593 | AG10: 0.068755701 | AH10: 0.037996273 | AI10: r jones | AJ10: 1.1025641 | AK10: 270 | AL10: 1 | AQ10: =IFERROR(IF($AN10="","",INDEX($H10:$M10,$AN10-0.5)),"line must be 1.5-6.5") | AR10: =IF(ISNUMBER($AQ10),1/$AQ10,"") | AS10: =IF(ISNUMBER($AQ10),1/(1-$AQ10),"") | AT10: =IF($AO10="","",IF($AP10="",1/$AO10,(1/$AO10)/((1/$AO10)+(1/$AP10)))) | AU10: =IF(OR(NOT(ISNUMBER($AQ10)),$AT10=""),"",$AQ10-$AT10) | AV10: =IF($AU10="","",IF($AU10>=0.05,"OVER",IF($AU10<=-0.05,"UNDER","skip"))) | AW10: =IF($AV10="OVER",$AQ10*$AO10-1,IF($AV10="UNDER",IF($AP10="","need under price",(1-$AQ10)*$AP10-1),"")) | AX10: =IF(OR($AV10="",$AV10="skip",$AL10="",$AN10=""),"",IF($AV10="OVER",IF($AL10>$AN10,"WON","LOST"),IF($AL10<$AN10,"WON","LOST"))) | AY10: =IF($AX10="","",IF($AX10="WON",IF($AV10="OVER",$AO10-1,$AP10-1),-1)) | AZ10: actual from BBC 2026-09-20 (provisional, ~97% exact vs football-data)
A11: 2026-09-20 | B11: E0 | C11: Premier League | D11: Fulham | E11: Man United | F11: 3.9 | G11: 3.5699775 | H11: 0.86183705 | I11: 0.68175342 | J11: 0.47399918 | K11: 0.2906353 | L11: 0.15861928 | M11: 0.077885447 | N11: 1.1603122 | O11: 1.466806 | P11: 2.1097083 | Q11: 3.4407383 | R11: 6.3044039 | S11: 12.839369 | T11: 7.2378301 | U11: 3.1422176 | V11: 1.9011377 | W11: 1.4097121 | X11: 1.1885226 | Y11: 1.084464 | Z11: 0.031966713 | AA11: 0.10619624 | AB11: 0.18008363 | AC11: 0.20775424 | AD11: 0.18336388 | AE11: 0.13201602 | AF11: 0.080733832 | AG11: 0.043120072 | AH11: 0.020525956 | AI11: p bankes | AJ11: 0.87179487 | AK11: 311 | AL11: 3 | AQ11: =IFERROR(IF($AN11="","",INDEX($H11:$M11,$AN11-0.5)),"line must be 1.5-6.5") | AR11: =IF(ISNUMBER($AQ11),1/$AQ11,"") | AS11: =IF(ISNUMBER($AQ11),1/(1-$AQ11),"") | AT11: =IF($AO11="","",IF($AP11="",1/$AO11,(1/$AO11)/((1/$AO11)+(1/$AP11)))) | AU11: =IF(OR(NOT(ISNUMBER($AQ11)),$AT11=""),"",$AQ11-$AT11) | AV11: =IF($AU11="","",IF($AU11>=0.05,"OVER",IF($AU11<=-0.05,"UNDER","skip"))) | AW11: =IF($AV11="OVER",$AQ11*$AO11-1,IF($AV11="UNDER",IF($AP11="","need under price",(1-$AQ11)*$AP11-1),"")) | AX11: =IF(OR($AV11="",$AV11="skip",$AL11="",$AN11=""),"",IF($AV11="OVER",IF($AL11>$AN11,"WON","LOST"),IF($AL11<$AN11,"WON","LOST"))) | AY11: =IF($AX11="","",IF($AX11="WON",IF($AV11="OVER",$AO11-1,$AP11-1),-1)) | AZ11: actual from BBC 2026-09-20 (provisional, ~97% exact vs football-data)
A12: 2026-09-18 | B12: E1 | C12: Championship | D12: Bristol City | E12: Watford | F12: 3.6987952 | G12: 3.972211 | H12: 0.89722788 | I12: 0.74604121 | J12: 0.55347881 | K12: 0.36584215 | L12: 0.21669571 | M12: 0.11599696 | N12: 1.1145441 | O12: 1.3404085 | P12: 1.8067539 | Q12: 2.7334193 | R12: 4.6147659 | S12: 8.6209159 | T12: 9.7302656 | U12: 3.9376467 | V12: 2.2395354 | W12: 1.5768945 | X12: 1.2766431 | Y12: 1.1312178 | Z12: 0.022017734 | AA12: 0.080754383 | AB12: 0.15118667 | AC12: 0.1925624 | AD12: 0.18763667 | AE12: 0.14914643 | AF12: 0.10069876 | AG12: 0.059378655 | AH12: 0.031205891 | AI12: o langford | AJ12: 0.64885993 | AK12: 524 | AL12: 7 | AQ12: =IFERROR(IF($AN12="","",INDEX($H12:$M12,$AN12-0.5)),"line must be 1.5-6.5") | AR12: =IF(ISNUMBER($AQ12),1/$AQ12,"") | AS12: =IF(ISNUMBER($AQ12),1/(1-$AQ12),"") | AT12: =IF($AO12="","",IF($AP12="",1/$AO12,(1/$AO12)/((1/$AO12)+(1/$AP12)))) | AU12: =IF(OR(NOT(ISNUMBER($AQ12)),$AT12=""),"",$AQ12-$AT12) | AV12: =IF($AU12="","",IF($AU12>=0.05,"OVER",IF($AU12<=-0.05,"UNDER","skip"))) | AW12: =IF($AV12="OVER",$AQ12*$AO12-1,IF($AV12="UNDER",IF($AP12="","need under price",(1-$AQ12)*$AP12-1),"")) | AX12: =IF(OR($AV12="",$AV12="skip",$AL12="",$AN12=""),"",IF($AV12="OVER",IF($AL12>$AN12,"WON","LOST"),IF($AL12<$AN12,"WON","LOST"))) | AY12: =IF($AX12="","",IF($AX12="WON",IF($AV12="OVER",$AO12-1,$AP12-1),-1)) | AZ12: actual from BBC 2026-09-18 (provisional, ~97% exact vs football-data)
A13: 2026-09-19 | B13: E1 | C13: Championship | D13: Cardiff | E13: Charlton | F13: 3.6987952 | G13: 3.5336396 | H13: 0.85812473 | I13: 0.6753599 | J13: 0.46651103 | K13: 0.28392823 | L13: 0.15372057 | M13: 0.074847404 | N13: 1.1653318 | O13: 1.480692 | P13: 2.143572 | Q13: 3.5220168 | R13: 6.5053102 | S13: 13.360517 | T13: 7.0484449 | U13: 3.0803342 | V13: 1.874453 | W13: 1.3965081 | X13: 1.1816428 | Y13: 1.0809028 | Z13: 0.033066539 | AA13: 0.10880873 | AB13: 0.18276484 | AC13: 0.20884887 | AD13: 0.1825828 | AE13: 0.13020766 | AF13: 0.078873168 | AG13: 0.041726987 | AH13: 0.019674548 | AI13: e bell | AJ13: 0.9732899 | AK13: 65 | AL13: 8 | AQ13: =IFERROR(IF($AN13="","",INDEX($H13:$M13,$AN13-0.5)),"line must be 1.5-6.5") | AR13: =IF(ISNUMBER($AQ13),1/$AQ13,"") | AS13: =IF(ISNUMBER($AQ13),1/(1-$AQ13),"") | AT13: =IF($AO13="","",IF($AP13="",1/$AO13,(1/$AO13)/((1/$AO13)+(1/$AP13)))) | AU13: =IF(OR(NOT(ISNUMBER($AQ13)),$AT13=""),"",$AQ13-$AT13) | AV13: =IF($AU13="","",IF($AU13>=0.05,"OVER",IF($AU13<=-0.05,"UNDER","skip"))) | AW13: =IF($AV13="OVER",$AQ13*$AO13-1,IF($AV13="UNDER",IF($AP13="","need under price",(1-$AQ13)*$AP13-1),"")) | AX13: =IF(OR($AV13="",$AV13="skip",$AL13="",$AN13=""),"",IF($AV13="OVER",IF($AL13>$AN13,"WON","LOST"),IF($AL13<$AN13,"WON","LOST"))) | AY13: =IF($AX13="","",IF($AX13="WON",IF($AV13="OVER",$AO13-1,$AP13-1),-1)) | AZ13: actual from BBC 2026-09-19 (provisional, ~97% exact vs football-data)
A14: 2026-09-19 | B14: E1 | C14: Championship | D14: Millwall | E14: West Ham | F14: 3.6987952 | G14: 3.387022 | H14: 0.84217156 | I14: 0.64855302 | J14: 0.43587464 | K14: 0.25714854 | L14: 0.13463007 | M14: 0.063290374 | N14: 1.1874065 | O14: 1.541894 | P14: 2.2942376 | Q14: 3.8888029 | R14: 7.4277612 | S14: 15.800191 | T14: 6.3359936 | U14: 2.8453794 | V14: 1.7726557 | W14: 1.3461641 | X14: 1.1555752 | Y14: 1.0675667 | Z14: 0.037911346 | AA14: 0.1199171 | AB14: 0.19361854 | AC14: 0.21267838 | AD14: 0.1787261 | AE14: 0.12251847 | AF14: 0.071339695 | AG14: 0.03627905 | AH14: 0.016442981 | AI14: p tierney | AJ14: 0.7029316 | AK14: 412 | AL14: 5 | AQ14: =IFERROR(IF($AN14="","",INDEX($H14:$M14,$AN14-0.5)),"line must be 1.5-6.5") | AR14: =IF(ISNUMBER($AQ14),1/$AQ14,"") | AS14: =IF(ISNUMBER($AQ14),1/(1-$AQ14),"") | AT14: =IF($AO14="","",IF($AP14="",1/$AO14,(1/$AO14)/((1/$AO14)+(1/$AP14)))) | AU14: =IF(OR(NOT(ISNUMBER($AQ14)),$AT14=""),"",$AQ14-$AT14) | AV14: =IF($AU14="","",IF($AU14>=0.05,"OVER",IF($AU14<=-0.05,"UNDER","skip"))) | AW14: =IF($AV14="OVER",$AQ14*$AO14-1,IF($AV14="UNDER",IF($AP14="","need under price",(1-$AQ14)*$AP14-1),"")) | AX14: =IF(OR($AV14="",$AV14="skip",$AL14="",$AN14=""),"",IF($AV14="OVER",IF($AL14>$AN14,"WON","LOST"),IF($AL14<$AN14,"WON","LOST"))) | AY14: =IF($AX14="","",IF($AX14="WON",IF($AV14="OVER",$AO14-1,$AP14-1),-1)) | AZ14: actual from BBC 2026-09-19 (provisional, ~97% exact vs football-data)
... A23: 2026-09-20 | B23: E1 | C23: Championship | D23: Norwich | E23: Bolton | F23: 3.6987952 | G23: 4.0589045 | H23: 0.90362778 | I23: 0.75839008 | J23: 0.56968314 | K23: 0.38210399 | L23: 0.23000363 | M23: 0.12524447 | N23: 1.1066503 | O23: 1.3185827 | P23: 1.7553617 | Q23: 2.6170886 | R23: 4.3477575 | S23: 7.9843843 | T23: 10.376434 | U23: 4.1389029 | V23: 2.323869 | W23: 1.6183953 | X23: 1.2987074 | Y23: 1.1431765 | Z23: 0.020325325 | AA23: 0.076046893 | AB23: 0.1452377 | AC23: 0.18870693 | AD23: 0.18757916 | AE23: 0.15210036 | AF23: 0.10475916 | AG23: 0.063015694 | AH23: 0.033783564 | AI23: t nield | AJ23: 0.9732899 | AK23: 219 | AL23: 0 | AQ23: =IFERROR(IF($AN23="","",INDEX($H23:$M23,$AN23-0.5)),"line must be 1.5-6.5") | AR23: =IF(ISNUMBER($AQ23),1/$AQ23,"") | AS23: =IF(ISNUMBER($AQ23),1/(1-$AQ23),"") | AT23: =IF($AO23="","",IF($AP23="",1/$AO23,(1/$AO23)/((1/$AO23)+(1/$AP23)))) | AU23: =IF(OR(NOT(ISNUMBER($AQ23)),$AT23=""),"",$AQ23-$AT23) | AV23: =IF($AU23="","",IF($AU23>=0.05,"OVER",IF($AU23<=-0.05,"UNDER","skip"))) | AW23: =IF($AV23="OVER",$AQ23*$AO23-1,IF($AV23="UNDER",IF($AP23="","need under price",(1-$AQ23)*$AP23-1),"")) | AX23: =IF(OR($AV23="",$AV23="skip",$AL23="",$AN23=""),"",IF($AV23="OVER",IF($AL23>$AN23,"WON","LOST"),IF($AL23<$AN23,"WON","LOST"))) | AY23: =IF($AX23="","",IF($AX23="WON",IF($AV23="OVER",$AO23-1,$AP23-1),-1)) | AZ23: actual from BBC 2026-09-20 (provisional, ~97% exact vs football-data)
A24: 2026-09-17 | B24: E2 | C24: League One | D24: AFC Wimbledon | E24: Milton Keynes Dons | F24: 3.55 | G24: 3.5697453 | H24: 0.86180636 | I24: 0.68170526 | J24: 0.47394818 | K24: 0.29059436 | L24: 0.15859279 | M24: 0.077871101 | N24: 1.1603535 | O24: 1.4669096 | P24: 2.1099353 | Q24: 3.441223 | R24: 6.3054569 | S24: 12.841735 | T24: 7.236223 | U24: 3.1417422 | V24: 1.9009534 | W24: 1.4096308 | X24: 1.1884852 | Y24: 1.0844471 | Z24: 0.031976626 | AA24: 0.10621701 | AB24: 0.1801011 | AC24: 0.20775709 | AD24: 0.18335381 | AE24: 0.13200157 | AF24: 0.08072169 | AG24: 0.043112385 | AH24: 0.020521983 | AI24: not known | AK24: 0 | AL24: 3 | AQ24: =IFERROR(IF($AN24="","",INDEX($H24:$M24,$AN24-0.5)),"line must be 1.5-6.5") | AR24: =IF(ISNUMBER($AQ24),1/$AQ24,"") | AS24: =IF(ISNUMBER($AQ24),1/(1-$AQ24),"") | AT24: =IF($AO24="","",IF($AP24="",1/$AO24,(1/$AO24)/((1/$AO24)+(1/$AP24)))) | AU24: =IF(OR(NOT(ISNUMBER($AQ24)),$AT24=""),"",$AQ24-$AT24) | AV24: =IF($AU24="","",IF($AU24>=0.05,"OVER",IF($AU24<=-0.05,"UNDER","skip"))) | AW24: =IF($AV24="OVER",$AQ24*$AO24-1,IF($AV24="UNDER",IF($AP24="","need under price",(1-$AQ24)*$AP24-1),"")) | AX24: =IF(OR($AV24="",$AV24="skip",$AL24="",$AN24=""),"",IF($AV24="OVER",IF($AL24>$AN24,"WON","LOST"),IF($AL24<$AN24,"WON","LOST"))) | AY24: =IF($AX24="","",IF($AX24="WON",IF($AV24="OVER",$AO24-1,$AP24-1),-1)) | AZ24: 3 yellows (1+2) per afcwimbledon.co.uk match report; football-data still had 0 -- cards lag a few days
A25: 2026-09-19 | B25: E2 | C25: League One | D25: Barnsley | E25: Leicester | F25: 3.4722222 | G25: 3.9333467 | H25: 0.89422828 | I25: 0.74033645 | J25: 0.54610064 | K25: 0.35854448 | L25: 0.21080986 | M25: 0.11196609 | N25: 1.1182827 | O25: 1.3507372 | P25: 1.8311643 | Q25: 2.7890542 | R25: 4.7436111 | S25: 8.9312753 | T25: 9.4543226 | U25: 3.8511374 | V25: 2.2031315 | W25: 1.5589545 | X25: 1.2671218 | Y25: 1.1260831 | Z25: 0.022822494 | AA25: 0.08294923 | AB25: 0.15389182 | AC25: 0.19423581 | AD25: 0.18755616 | AE25: 0.14773462 | AF25: 0.098843771 | AG25: 0.057757891 | AH25: 0.030079689 | AI25: s stockbridge | AJ25: 1.1808 | AK25: 359 | AL25: 8 | AQ25: =IFERROR(IF($AN25="","",INDEX($H25:$M25,$AN25-0.5)),"line must be 1.5-6.5") | AR25: =IF(ISNUMBER($AQ25),1/$AQ25,"") | AS25: =IF(ISNUMBER($AQ25),1/(1-$AQ25),"") | AT25: =IF($AO25="","",IF($AP25="",1/$AO25,(1/$AO25)/((1/$AO25)+(1/$AP25)))) | AU25: =IF(OR(NOT(ISNUMBER($AQ25)),$AT25=""),"",$AQ25-$AT25) | AV25: =IF($AU25="","",IF($AU25>=0.05,"OVER",IF($AU25<=-0.05,"UNDER","skip"))) | AW25: =IF($AV25="OVER",$AQ25*$AO25-1,IF($AV25="UNDER",IF($AP25="","need under price",(1-$AQ25)*$AP25-1),"")) | AX25: =IF(OR($AV25="",$AV25="skip",$AL25="",$AN25=""),"",IF($AV25="OVER",IF($AL25>$AN25,"WON","LOST"),IF($AL25<$AN25,"WON","LOST"))) | AY25: =IF($AX25="","",IF($AX25="WON",IF($AV25="OVER",$AO25-1,$AP25-1),-1)) | AZ25: actual from BBC 2026-09-19 (provisional, ~97% exact vs football-data)
A26: 2026-09-19 | B26: E2 | C26: League One | D26: Burton | E26: Mansfield | F26: 3.4722222 | G26: 3.6411037 | H26: 0.8688394 | I26: 0.69398216 | J26: 0.48852256 | K26: 0.30382655 | L26: 0.16838948 | M26: 0.084030054 | N26: 1.1509607 | O26: 1.4409592 | P26: 2.0469884 | Q26: 3.2913516 | R26: 5.9386131 | S26: 11.900504 | T26: 7.6242405 | U26: 3.2677833 | V26: 1.9551204 | W26: 1.4364236 | X26: 1.202486 | Y26: 1.0917389 | Z26: 0.029920788 | AA26: 0.10123982 | AB26: 0.17485724 | AC26: 0.2054596 | AD26: 0.18469601 | AE26: 0.13543706 | AF26: 0.084359429 | AG26: 0.045890704 | AH26: 0.022249272 | AI26: o mackey | AJ26: 0.9792 | AK26: 24 | AL26: 6 | AQ26: =IFERROR(IF($AN26="","",INDEX($H26:$M26,$AN26-0.5)),"line must be 1.5-6.5") | AR26: =IF(ISNUMBER($AQ26),1/$AQ26,"") | AS26: =IF(ISNUMBER($AQ26),1/(1-$AQ26),"") | AT26: =IF($AO26="","",IF($AP26="",1/$AO26,(1/$AO26)/((1/$AO26)+(1/$AP26)))) | AU26: =IF(OR(NOT(ISNUMBER($AQ26)),$AT26=""),"",$AQ26-$AT26) | AV26: =IF($AU26="","",IF($AU26>=0.05,"OVER",IF($AU26<=-0.05,"UNDER","skip"))) | AW26: =IF($AV26="OVER",$AQ26*$AO26-1,IF($AV26="UNDER",IF($AP26="","need under price",(1-$AQ26)*$AP26-1),"")) | AX26: =IF(OR($AV26="",$AV26="skip",$AL26="",$AN26=""),"",IF($AV26="OVER",IF($AL26>$AN26,"WON","LOST"),IF($AL26<$AN26,"WON","LOST"))) | AY26: =IF($AX26="","",IF($AX26="WON",IF($AV26="OVER",$AO26-1,$AP26-1),-1)) | AZ26: actual from BBC 2026-09-19 (provisional, ~97% exact vs football-data)
A27: 2026-09-19 | B27: E2 | C27: League One | D27: Blackpool | E27: Plymouth | F27: 3.4722222 | G27: 3.9743983 | H27: 0.89739426 | I27: 0.74635915 | J27: 0.55389199 | K27: 0.36625278 | L27: 0.2170285 | M27: 0.11622595 | N27: 1.1143374 | O27: 1.3398375 | P27: 1.8054061 | Q27: 2.7303547 | R27: 4.6076899 | S27: 8.6039307 | T27: 9.7460431 | U27: 3.9425826 | V27: 2.2416096 | W27: 1.5779162 | X27: 1.2771857 | Y27: 1.1315109 | Z27: 0.021973312 | AA27: 0.080632431 | AB27: 0.15103511 | AC27: 0.19246716 | AD27: 0.18763921 | AE27: 0.14922429 | AF27: 0.10080255 | AG27: 0.059470075 | AH27: 0.031269826 | AI27: d drysdale | AJ27: 1.296 | AK27: 497 | AL27: 3 | AQ27: =IFERROR(IF($AN27="","",INDEX($H27:$M27,$AN27-0.5)),"line must be 1.5-6.5") | AR27: =IF(ISNUMBER($AQ27),1/$AQ27,"") | AS27: =IF(ISNUMBER($AQ27),1/(1-$AQ27),"") | AT27: =IF($AO27="","",IF($AP27="",1/$AO27,(1/$AO27)/((1/$AO27)+(1/$AP27)))) | AU27: =IF(OR(NOT(ISNUMBER($AQ27)),$AT27=""),"",$AQ27-$AT27) | AV27: =IF($AU27="","",IF($AU27>=0.05,"OVER",IF($AU27<=-0.05,"UNDER","skip"))) | AW27: =IF($AV27="OVER",$AQ27*$AO27-1,IF($AV27="UNDER",IF($AP27="","need under price",(1-$AQ27)*$AP27-1),"")) | AX27: =IF(OR($AV27="",$AV27="skip",$AL27="",$AN27=""),"",IF($AV27="OVER",IF($AL27>$AN27,"WON","LOST"),IF($AL27<$AN27,"WON","LOST"))) | AY27: =IF($AX27="","",IF($AX27="WON",IF($AV27="OVER",$AO27-1,$AP27-1),-1)) | AZ27: actual from BBC 2026-09-19 (provisional, ~97% exact vs football-data)
A28: 2026-09-19 | B28: E2 | C28: League One | D28: Bromley | E28: Huddersfield | F28: 3.4722222 | G28: 3.6706726 | H28: 0.87165044 | I28: 0.6989553 | J28: 0.49450574 | K28: 0.30933152 | L28: 0.17251966 | M28: 0.086661193 | N28: 1.1472489 | O28: 1.4307067 | P28: 2.0222212 | Q28: 3.2327775 | R28: 5.7964409 | S28: 11.53919 | T28: 7.7912224 | U28: 3.3217658 | V28: 1.9782618 | W28: 1.4478727 | X28: 1.2084879 | Y28: 1.0948839 | Z28: 0.029110055 | AA28: 0.099239509 | AB28: 0.17269514 | AC28: 0.20444956 | AD28: 0.18517421 | AE28: 0.13681187 | AF28: 0.085858464 | AG28: 0.047058431 | AH28: 0.022987502 | AI28: c brook | AJ28: 0.9792 | AK28: 165 | AL28: 4 | AQ28: =IFERROR(IF($AN28="","",INDEX($H28:$M28,$AN28-0.5)),"line must be 1.5-6.5") | AR28: =IF(ISNUMBER($AQ28),1/$AQ28,"") | AS28: =IF(ISNUMBER($AQ28),1/(1-$AQ28),"") | AT28: =IF($AO28="","",IF($AP28="",1/$AO28,(1/$AO28)/((1/$AO28)+(1/$AP28)))) | AU28: =IF(OR(NOT(ISNUMBER($AQ28)),$AT28=""),"",$AQ28-$AT28) | AV28: =IF($AU28="","",IF($AU28>=0.05,"OVER",IF($AU28<=-0.05,"UNDER","skip"))) | AW28: =IF($AV28="OVER",$AQ28*$AO28-1,IF($AV28="UNDER",IF($AP28="","need under price",(1-$AQ28)*$AP28-1),"")) | AX28: =IF(OR($AV28="",$AV28="skip",$AL28="",$AN28=""),"",IF($AV28="OVER",IF($AL28>$AN28,"WON","LOST"),IF($AL28<$AN28,"WON","LOST"))) | AY28: =IF($AX28="","",IF($AX28="WON",IF($AV28="OVER",$AO28-1,$AP28-1),-1)) | AZ28: actual from BBC 2026-09-19 (provisional, ~97% exact vs football-data)
A29: 2026-09-19 | B29: E2 | C29: League One | D29: Leyton Orient | E29: Stevenage | F29: 3.4722222 | G29: 3.3627578 | H29: 0.83937453 | I29: 0.64395994 | J29: 0.43074544 | K29: 0.25276811 | L29: 0.13157955 | M29: 0.061486561 | N29: 1.1913633 | O29: 1.5528916 | P29: 2.3215568 | Q29: 3.9561953 | R29: 7.599965 | S29: 16.263717 | T29: 6.2256628 | U29: 2.8086727 | V29: 1.7566833 | W29: 1.3382726 | X29: 1.151516 | Y29: 1.0655148 | Z29: 0.03878043 | AA29: 0.12184504 | AB29: 0.1954146 | AC29: 0.21321449 | AD29: 0.17797733 | AE29: 0.12118855 | AF29: 0.070092993 | AG29: 0.035406466 | AH29: 0.015940083 | AI29: c hicks | AJ29: 0.6048 | AK29: 223 | AL29: 4 | AQ29: =IFERROR(IF($AN29="","",INDEX($H29:$M29,$AN29-0.5)),"line must be 1.5-6.5") | AR29: =IF(ISNUMBER($AQ29),1/$AQ29,"") | AS29: =IF(ISNUMBER($AQ29),1/(1-$AQ29),"") | AT29: =IF($AO29="","",IF($AP29="",1/$AO29,(1/$AO29)/((1/$AO29)+(1/$AP29)))) | AU29: =IF(OR(NOT(ISNUMBER($AQ29)),$AT29=""),"",$AQ29-$AT29) | AV29: =IF($AU29="","",IF($AU29>=0.05,"OVER",IF($AU29<=-0.05,"UNDER","skip"))) | AW29: =IF($AV29="OVER",$AQ29*$AO29-1,IF($AV29="UNDER",IF($AP29="","need under price",(1-$AQ29)*$AP29-1),"")) | AX29: =IF(OR($AV29="",$AV29="skip",$AL29="",$AN29=""),"",IF($AV29="OVER",IF($AL29>$AN29,"WON","LOST"),IF($AL29<$AN29,"WON","LOST"))) | AY29: =IF($AX29="","",IF($AX29="WON",IF($AV29="OVER",$AO29-1,$AP29-1),-1)) | AZ29: actual from BBC 2026-09-19 (provisional, ~97% exact vs football-data)
A30: 2026-09-19 | B30: E2 | C30: League One | D30: Luton | E30: Bradford | F30: 3.4722222 | G30: 4.4557242 | H30: 0.92833399 | I30: 0.8085972 | J30: 0.63910966 | K30: 0.45556736 | L30: 0.29342986 | M30: 0.17177011 | N30: 1.0771985 | O30: 1.2367097 | P30: 1.5646767 | Q30: 2.1950651 | R30: 3.4079695 | S30: 5.8217345 | T30: 13.953616 | U30: 5.2245838 | V30: 2.7709248 | W30: 1.8367745 | X30: 1.4152877 | Y30: 1.2073942 | Z30: 0.0141183 | AA30: 0.057547711 | AB30: 0.11973679 | AC30: 0.16948754 | AD30: 0.1835423 | AE30: 0.1621375 | AF30: 0.12165974 | AG30: 0.079726978 | AH30: 0.046565439 | AI30: r martin | AJ30: 0.864 | AK30: 22 | AL30: 5 | AQ30: =IFERROR(IF($AN30="","",INDEX($H30:$M30,$AN30-0.5)),"line must be 1.5-6.5") | AR30: =IF(ISNUMBER($AQ30),1/$AQ30,"") | AS30: =IF(ISNUMBER($AQ30),1/(1-$AQ30),"") | AT30: =IF($AO30="","",IF($AP30="",1/$AO30,(1/$AO30)/((1/$AO30)+(1/$AP30)))) | AU30: =IF(OR(NOT(ISNUMBER($AQ30)),$AT30=""),"",$AQ30-$AT30) | AV30: =IF($AU30="","",IF($AU30>=0.05,"OVER",IF($AU30<=-0.05,"UNDER","skip"))) | AW30: =IF($AV30="OVER",$AQ30*$AO30-1,IF($AV30="UNDER",IF($AP30="","need under price",(1-$AQ30)*$AP30-1),"")) | AX30: =IF(OR($AV30="",$AV30="skip",$AL30="",$AN30=""),"",IF($AV30="OVER",IF($AL30>$AN30,"WON","LOST"),IF($AL30<$AN30,"WON","LOST"))) | AY30: =IF($AX30="","",IF($AX30="WON",IF($AV30="OVER",$AO30-1,$AP30-1),-1)) | AZ30: actual from BBC 2026-09-19 (provisional, ~97% exact vs football-data)
A31: 2026-09-19 | B31: E2 | C31: League One | D31: Oxford | E31: Cambridge | F31: 3.4722222 | G31: 3.3323546 | H31: 0.83580446 | I31: 0.63814182 | J31: 0.42429742 | K31: 0.24730307 | L31: 0.12780253 | M31: 0.059270049 | N31: 1.1964521 | O31: 1.5670498 | P31: 2.3568373 | Q31: 4.0436215 | R31: 7.8245714 | S31: 16.871928 | T31: 6.0902995 | U31: 2.7635136 | V31: 1.737008 | W31: 1.328556 | X31: 1.1465293 | Y31: 1.0630043 | Z31: 0.039898181 | AA31: 0.12429736 | AB31: 0.19766264 | AC31: 0.2138444 | AD31: 0.17699435 | AE31: 0.11950054 | AF31: 0.068532477 | AG31: 0.034325587 | AH31: 0.015322849 | AI31: t kirk | AJ31: 0.9504 | AK31: 113 | AL31: 6 | AQ31: =IFERROR(IF($AN31="","",INDEX($H31:$M31,$AN31-0.5)),"line must be 1.5-6.5") | AR31: =IF(ISNUMBER($AQ31),1/$AQ31,"") | AS31: =IF(ISNUMBER($AQ31),1/(1-$AQ31),"") | AT31: =IF($AO31="","",IF($AP31="",1/$AO31,(1/$AO31)/((1/$AO31)+(1/$AP31)))) | AU31: =IF(OR(NOT(ISNUMBER($AQ31)),$AT31=""),"",$AQ31-$AT31) | AV31: =IF($AU31="","",IF($AU31>=0.05,"OVER",IF($AU31<=-0.05,"UNDER","skip"))) | AW31: =IF($AV31="OVER",$AQ31*$AO31-1,IF($AV31="UNDER",IF($AP31="","need under price",(1-$AQ31)*$AP31-1),"")) | AX31: =IF(OR($AV31="",$AV31="skip",$AL31="",$AN31=""),"",IF($AV31="OVER",IF($AL31>$AN31,"WON","LOST"),IF($AL31<$AN31,"WON","LOST"))) | AY31: =IF($AX31="","",IF($AX31="WON",IF($AV31="OVER",$AO31-1,$AP31-1),-1)) | AZ31: actual from BBC 2026-09-19 (provisional, ~97% exact vs football-data)
A32: 2026-09-19 | B32: E2 | C32: League One | D32: Peterboro | E32: Doncaster | F32: 3.4722222 | G32: 3.2509877 | H32: 0.82588296 | I32: 0.62222686 | J32: 0.40693586 | K32: 0.2328183 | L32: 0.11794788 | M32: 0.053576929 | N32: 1.2108253 | O32: 1.6071309 | P32: 2.4573897 | Q32: 4.295195 | R32: 8.478321 | S32: 18.66475 | T32: 5.7432633 | U32: 2.6470913 | V32: 1.6861583 | W32: 1.3034722 | X32: 1.1337199 | Y32: 1.0566099 | Z32: 0.043054207 | AA32: 0.13106283 | AB32: 0.2036561 | AC32: 0.215291 | AD32: 0.17411756 | AE32: 0.11487042 | AF32: 0.064370952 | AG32: 0.031504068 | AH32: 0.013741791 | AI32: w davis | AJ32: 0.8352 | AK32: 10 | AL32: 3 | AQ32: =IFERROR(IF($AN32="","",INDEX($H32:$M32,$AN32-0.5)),"line must be 1.5-6.5") | AR32: =IF(ISNUMBER($AQ32),1/$AQ32,"") | AS32: =IF(ISNUMBER($AQ32),1/(1-$AQ32),"") | AT32: =IF($AO32="","",IF($AP32="",1/$AO32,(1/$AO32)/((1/$AO32)+(1/$AP32)))) | AU32: =IF(OR(NOT(ISNUMBER($AQ32)),$AT32=""),"",$AQ32-$AT32) | AV32: =IF($AU32="","",IF($AU32>=0.05,"OVER",IF($AU32<=-0.05,"UNDER","skip"))) | AW32: =IF($AV32="OVER",$AQ32*$AO32-1,IF($AV32="UNDER",IF($AP32="","need under price",(1-$AQ32)*$AP32-1),"")) | AX32: =IF(OR($AV32="",$AV32="skip",$AL32="",$AN32=""),"",IF($AV32="OVER",IF($AL32>$AN32,"WON","LOST"),IF($AL32<$AN32,"WON","LOST"))) | AY32: =IF($AX32="","",IF($AX32="WON",IF($AV32="OVER",$AO32-1,$AP32-1),-1)) | AZ32: actual from BBC 2026-09-19 (provisional, ~97% exact vs football-data)
A33: 2026-09-19 | B33: E2 | C33: League One | D33: Reading | E33: Notts County | F33: 3.4722222 | G33: 3.7921776 | H33: 0.88261244 | I33: 0.71871631 | J33: 0.5187326 | K33: 0.33204786 | L33: 0.18988966 | M33: 0.097939786 | N33: 1.1330001 | O33: 1.3913696 | P33: 1.9277755 | Q33: 3.011614 | R33: 5.2662162 | S33: 10.210355 | T33: 8.5187904 | U33: 3.5551297 | V33: 2.077847 | W33: 1.4971133 | X33: 1.2343997 | Y33: 1.1085734 | Z33: 0.026007098 | AA33: 0.091380459 | AB33: 0.16389613 | AC33: 0.19998371 | AD33: 0.18668474 | AE33: 0.1421582 | AF33: 0.091949873 | AG33: 0.051942796 | AH33: 0.026151675 | AI33: s mather | AJ33: 0.9504 | AK33: 149 | AL33: 3 | AQ33: =IFERROR(IF($AN33="","",INDEX($H33:$M33,$AN33-0.5)),"line must be 1.5-6.5") | AR33: =IF(ISNUMBER($AQ33),1/$AQ33,"") | AS33: =IF(ISNUMBER($AQ33),1/(1-$AQ33),"") | AT33: =IF($AO33="","",IF($AP33="",1/$AO33,(1/$AO33)/((1/$AO33)+(1/$AP33)))) | AU33: =IF(OR(NOT(ISNUMBER($AQ33)),$AT33=""),"",$AQ33-$AT33) | AV33: =IF($AU33="","",IF($AU33>=0.05,"OVER",IF($AU33<=-0.05,"UNDER","skip"))) | AW33: =IF($AV33="OVER",$AQ33*$AO33-1,IF($AV33="UNDER",IF($AP33="","need under price",(1-$AQ33)*$AP33-1),"")) | AX33: =IF(OR($AV33="",$AV33="skip",$AL33="",$AN33=""),"",IF($AV33="OVER",IF($AL33>$AN33,"WON","LOST"),IF($AL33<$AN33,"WON","LOST"))) | AY33: =IF($AX33="","",IF($AX33="WON",IF($AV33="OVER",$AO33-1,$AP33-1),-1)) | AZ33: actual from BBC 2026-09-19 (provisional, ~97% exact vs football-data)
A34: 2026-09-19 | B34: E2 | C34: League One | D34: Sheffield Weds | E34: Stockport | F34: 3.4722222 | G34: 3.5076543 | H34: 0.85541262 | I34: 0.67072709 | J34: 0.46112935 | K34: 0.27914728 | L34: 0.15025721 | M34: 0.072717081 | N34: 1.1690265 | O34: 1.4909194 | P34: 2.1685889 | Q34: 3.5823383 | R34: 6.6552549 | S34: 13.751927 | T34: 6.9162328 | U34: 3.0369944 | V34: 1.8557329 | W34: 1.3872459 | X34: 1.1768267 | Y34: 1.0784195 | Z34: 0.033876652 | AA34: 0.11071073 | AB34: 0.18468553 | AC34: 0.20959774 | AD34: 0.18198206 | AE34: 0.12889008 | AF34: 0.077540124 | AG34: 0.040740699 | AH34: 0.019077896 | AI34: b toner | AJ34: 1.152 | AK34: 310 | AL34: 4 | AQ34: =IFERROR(IF($AN34="","",INDEX($H34:$M34,$AN34-0.5)),"line must be 1.5-6.5") | AR34: =IF(ISNUMBER($AQ34),1/$AQ34,"") | AS34: =IF(ISNUMBER($AQ34),1/(1-$AQ34),"") | AT34: =IF($AO34="","",IF($AP34="",1/$AO34,(1/$AO34)/((1/$AO34)+(1/$AP34)))) | AU34: =IF(OR(NOT(ISNUMBER($AQ34)),$AT34=""),"",$AQ34-$AT34) | AV34: =IF($AU34="","",IF($AU34>=0.05,"OVER",IF($AU34<=-0.05,"UNDER","skip"))) | AW34: =IF($AV34="OVER",$AQ34*$AO34-1,IF($AV34="UNDER",IF($AP34="","need under price",(1-$AQ34)*$AP34-1),"")) | AX34: =IF(OR($AV34="",$AV34="skip",$AL34="",$AN34=""),"",IF($AV34="OVER",IF($AL34>$AN34,"WON","LOST"),IF($AL34<$AN34,"WON","LOST"))) | AY34: =IF($AX34="","",IF($AX34="WON",IF($AV34="OVER",$AO34-1,$AP34-1),-1)) | AZ34: actual from BBC 2026-09-19 (provisional, ~97% exact vs football-data)
A35: 2026-09-19 | B35: E2 | C35: League One | D35: Wigan | E35: Wycombe | F35: 3.4722222 | G35: 3.4513518 | H35: 0.84936802 | I35: 0.66051466 | J35: 0.44939564 | K35: 0.26883703 | L35: 0.14286967 | M35: 0.068222409 | N35: 1.1773459 | O35: 1.5139709 | P35: 2.2252107 | Q35: 3.7197257 | R35: 6.999386 | S35: 14.65794 | T35: 6.6386967 | U35: 2.9456353 | V35: 1.8161861 | W35: 1.3676841 | X35: 1.1666837 | Y35: 1.0732175 | Z35: 0.035702166 | AA35: 0.11492981 | AB35: 0.18885337 | AC35: 0.21111901 | AD35: 0.18055861 | AE35: 0.12596736 | AF35: 0.074647265 | AG35: 0.038633564 | AH35: 0.017820326 | AI35: d whitestone | AJ35: 0.864 | AK35: 580 | AL35: 7 | AQ35: =IFERROR(IF($AN35="","",INDEX($H35:$M35,$AN35-0.5)),"line must be 1.5-6.5") | AR35: =IF(ISNUMBER($AQ35),1/$AQ35,"") | AS35: =IF(ISNUMBER($AQ35),1/(1-$AQ35),"") | AT35: =IF($AO35="","",IF($AP35="",1/$AO35,(1/$AO35)/((1/$AO35)+(1/$AP35)))) | AU35: =IF(OR(NOT(ISNUMBER($AQ35)),$AT35=""),"",$AQ35-$AT35) | AV35: =IF($AU35="","",IF($AU35>=0.05,"OVER",IF($AU35<=-0.05,"UNDER","skip"))) | AW35: =IF($AV35="OVER",$AQ35*$AO35-1,IF($AV35="UNDER",IF($AP35="","need under price",(1-$AQ35)*$AP35-1),"")) | AX35: =IF(OR($AV35="",$AV35="skip",$AL35="",$AN35=""),"",IF($AV35="OVER",IF($AL35>$AN35,"WON","LOST"),IF($AL35<$AN35,"WON","LOST"))) | AY35: =IF($AX35="","",IF($AX35="WON",IF($AV35="OVER",$AO35-1,$AP35-1),-1)) | AZ35: actual from BBC 2026-09-19 (provisional, ~97% exact vs football-data)
A36: 2026-09-19 | B36: E3 | C36: League Two | D36: Rochdale | E36: Oldham | F36: 3.9444444 | G36: 3.7031518 | H36: 0.87467228 | I36: 0.70434349 | J36: 0.50103932 | K36: 0.31539027 | L36: 0.17710112 | M36: 0.089602826 | N36: 1.1432853 | O36: 1.4197618 | P36: 1.9958513 | Q36: 3.1706748 | R36: 5.6464916 | S36: 11.160362 | T36: 7.9790807 | U36: 3.3823033 | V36: 2.0041659 | W36: 1.4606862 | X36: 1.2152161 | Y36: 1.0984217 | Z36: 0.028245335 | AA36: 0.097082386 | AB36: 0.17032879 | AC36: 0.20330416 | AD36: 0.18564905 | AE36: 0.13828915 | AF36: 0.087498295 | AG36: 0.048351066 | AH36: 0.023812912 | AI36: s parkinson | AJ36: 0.83661972 | AK36: 41 | AL36: 0 | AQ36: =IFERROR(IF($AN36="","",INDEX($H36:$M36,$AN36-0.5)),"line must be 1.5-6.5") | AR36: =IF(ISNUMBER($AQ36),1/$AQ36,"") | AS36: =IF(ISNUMBER($AQ36),1/(1-$AQ36),"") | AT36: =IF($AO36="","",IF($AP36="",1/$AO36,(1/$AO36)/((1/$AO36)+(1/$AP36)))) | AU36: =IF(OR(NOT(ISNUMBER($AQ36)),$AT36=""),"",$AQ36-$AT36) | AV36: =IF($AU36="","",IF($AU36>=0.05,"OVER",IF($AU36<=-0.05,"UNDER","skip"))) | AW36: =IF($AV36="OVER",$AQ36*$AO36-1,IF($AV36="UNDER",IF($AP36="","need under price",(1-$AQ36)*$AP36-1),"")) | AX36: =IF(OR($AV36="",$AV36="skip",$AL36="",$AN36=""),"",IF($AV36="OVER",IF($AL36>$AN36,"WON","LOST"),IF($AL36<$AN36,"WON","LOST"))) | AY36: =IF($AX36="","",IF($AX36="WON",IF($AV36="OVER",$AO36-1,$AP36-1),-1)) | AZ36: actual from BBC 2026-09-19 (provisional, ~97% exact vs football-data)
... A47: 2026-09-19 | B47: E3 | C47: League Two | D47: Salford | E47: Swindon | F47: 3.9444444 | G47: 3.3556927 | H47: 0.83855144 | I47: 0.64261416 | J47: 0.4292491 | K47: 0.25149574 | L47: 0.13069733 | M47: 0.060967154 | N47: 1.1925327 | O47: 1.5561437 | P47: 2.3296496 | Q47: 3.9762104 | R47: 7.6512658 | S47: 16.402275 | T47: 6.1939234 | U47: 2.7980963 | V47: 1.7520778 | W47: 1.3359977 | X47: 1.1503473 | Y47: 1.0649255 | Z47: 0.039037289 | AA47: 0.12241127 | AB47: 0.19593728 | AC47: 0.21336507 | AD47: 0.17775336 | AE47: 0.12079842 | AF47: 0.069730175 | AG47: 0.035154041 | AH47: 0.015795368 | AI47: n hair | AJ47: 1.0140845 | AK47: 170 | AL47: 3 | AQ47: =IFERROR(IF($AN47="","",INDEX($H47:$M47,$AN47-0.5)),"line must be 1.5-6.5") | AR47: =IF(ISNUMBER($AQ47),1/$AQ47,"") | AS47: =IF(ISNUMBER($AQ47),1/(1-$AQ47),"") | AT47: =IF($AO47="","",IF($AP47="",1/$AO47,(1/$AO47)/((1/$AO47)+(1/$AP47)))) | AU47: =IF(OR(NOT(ISNUMBER($AQ47)),$AT47=""),"",$AQ47-$AT47) | AV47: =IF($AU47="","",IF($AU47>=0.05,"OVER",IF($AU47<=-0.05,"UNDER","skip"))) | AW47: =IF($AV47="OVER",$AQ47*$AO47-1,IF($AV47="UNDER",IF($AP47="","need under price",(1-$AQ47)*$AP47-1),"")) | AX47: =IF(OR($AV47="",$AV47="skip",$AL47="",$AN47=""),"",IF($AV47="OVER",IF($AL47>$AN47,"WON","LOST"),IF($AL47<$AN47,"WON","LOST"))) | AY47: =IF($AX47="","",IF($AX47="WON",IF($AV47="OVER",$AO47-1,$AP47-1),-1)) | AZ47: actual from BBC 2026-09-19 (provisional, ~97% exact vs football-data)
D48: EXAMPLE OF A COMPLETED ROW (not a real fixture, not counted anywhere)
A49: 2026-09-19 | B49: E0 | C49: Premier League | D49: Example FC | E49: Sample United | F49: 3.87 | G49: 4.4 | J49: 0.63 | P49: 1.59 | V49: 2.7 | AI49: a referee | AJ49: 1.2 | AK49: 200 | AL49: 5 | AM49: Bet365 | AN49: 3.5 | AO49: 1.8 | AP49: 2.05 | AQ49: 0.63 | AR49: 1.59 | AS49: 2.7 | AT49: 0.532 | AU49: 0.098 | AV49: OVER | AW49: 0.134 | AX49: WON | AY49: 0.8 | AZ49: 5 yellows > 3.5, so the OVER won at 1.80: +0.80 units

Sheet Scoring
A1: Metric | B1: Value | C1: What it means
A2: Matches predicted | B2: =COUNTA(Predictions!$D$2:$D$47)
A3: Results entered | B3: =COUNT(Predictions!$AL$2:$AL$47) | C3: Fill the yellow ACTUAL column in.
A4: Mean predicted (filled rows) | B4: =IF(COUNT(Predictions!$AL$2:$AL$47)=0,"",SUMPRODUCT(--ISNUMBER(Predictions!$AL$2:$AL$47),Predictions!$G$2:$G$47)/COUNT(Predictions!$AL$2:$AL$47)) | C4: Averaged over only the matches you have entered.
A5: Mean actual | B5: =IF(COUNT(Predictions!$AL$2:$AL$47)=0,"",AVERAGE(Predictions!$AL$2:$AL$47))
A6: Bias (actual - predicted) | B6: =IF(COUNT(Predictions!$AL$2:$AL$47)=0,"",AVERAGE(Predictions!$AL$2:$AL$47)-SUMPRODUCT(--ISNUMBER(Predictions!$AL$2:$AL$47),Predictions!$G$2:$G$47)/COUNT(Predictions!$AL$2:$AL$47)) | C6: Positive = the model under-predicts cards.
A7: Mean absolute error | B7: =IF(COUNT(Predictions!$AL$2:$AL$47)=0,"",SUMPRODUCT(--ISNUMBER(Predictions!$AL$2:$AL$47),ABS(Predictions!$AL$2:$AL$47-Predictions!$G$2:$G$47))/COUNT(Predictions!$AL$2:$AL$47)) | C7: Expect ~1.5. Match cards are genuinely noisy.
A9: CALIBRATION -- THE NUMBER THAT MATTERS
A10: Predicted over 3.5 | B10: =IF(COUNT(Predictions!$AL$2:$AL$47)=0,"",SUMPRODUCT(--ISNUMBER(Predictions!$AL$2:$AL$47),Predictions!$J$2:$J$47)/COUNT(Predictions!$AL$2:$AL$47))
A11: Actual share over 3.5 | B11: =IF(COUNT(Predictions!$AL$2:$AL$47)=0,"",COUNTIF(Predictions!$AL$2:$AL$47,">3.5")/COUNT(Predictions!$AL$2:$AL$47))
A12: Calibration gap | B12: =IF(COUNT(Predictions!$AL$2:$AL$47)=0,"",SUMPRODUCT(--ISNUMBER(Predictions!$AL$2:$AL$47),Predictions!$J$2:$J$47)/COUNT(Predictions!$AL$2:$AL$47)-COUNTIF(Predictions!$AL$2:$AL$47,">3.5")/COUNT(Predictions!$AL$2:$AL$47)) | C12: Near zero = well calibrated. This is the whole test.
A13: Predicted over 2.5 | B13: =IF(COUNT(Predictions!$AL$2:$AL$47)=0,"",SUMPRODUCT(--ISNUMBER(Predictions!$AL$2:$AL$47),Predictions!$I$2:$I$47)/COUNT(Predictions!$AL$2:$AL$47))
A14: Actual share over 2.5 | B14: =IF(COUNT(Predictions!$AL$2:$AL$47)=0,"",COUNTIF(Predictions!$AL$2:$AL$47,">2.5")/COUNT(Predictions!$AL$2:$AL$47))
A15: Predicted over 4.5 | B15: =IF(COUNT(Predictions!$AL$2:$AL$47)=0,"",SUMPRODUCT(--ISNUMBER(Predictions!$AL$2:$AL$47),Predictions!$K$2:$K$47)/COUNT(Predictions!$AL$2:$AL$47))
A16: Actual share over 4.5 | B16: =IF(COUNT(Predictions!$AL$2:$AL$47)=0,"",COUNTIF(Predictions!$AL$2:$AL$47,">4.5")/COUNT(Predictions!$AL$2:$AL$47))
A18: BETTING -- ONLY IF YOU ENTERED PRICES
A19: Bets the model would place | B19: =COUNTIF(Predictions!$AV$2:$AV$47,"OVER")+COUNTIF(Predictions!$AV$2:$AV$47,"UNDER") | C19: Edge of 5 points or more. Most fixtures should be skips.
A20: of which OVER | B20: =COUNTIF(Predictions!$AV$2:$AV$47,"OVER")
A21: of which UNDER | B21: =COUNTIF(Predictions!$AV$2:$AV$47,"UNDER") | C21: A model below the price is an edge too.
A22: Bets settled | B22: =COUNTIF(Predictions!$AX$2:$AX$47,"WON")+COUNTIF(Predictions!$AX$2:$AX$47,"LOST")
A23: Bets won | B23: =COUNTIF(Predictions!$AX$2:$AX$47,"WON")
A24: Strike rate | B24: =IF(COUNTIF(Predictions!$AX$2:$AX$47,"WON")+COUNTIF(Predictions!$AX$2:$AX$47,"LOST")=0,"",COUNTIF(Predictions!$AX$2:$AX$47,"WON")/(COUNTIF(Predictions!$AX$2:$AX$47,"WON")+COUNTIF(Predictions!$AX$2:$AX$47,"LOST"))) | C24: Means nothing on its own -- a 40% strike rate at long prices wins.
A25: Profit / loss (units) | B25: =IF(COUNT(Predictions!$AY$2:$AY$47)=0,"",SUM(Predictions!$AY$2:$AY$47)) | C25: One unit staked per bet. This is the number that matters.
A26: ROI | B26: =IF(COUNTIF(Predictions!$AX$2:$AX$47,"WON")+COUNTIF(Predictions!$AX$2:$AX$47,"LOST")=0,"",SUM(Predictions!$AY$2:$AY$47)/(COUNTIF(Predictions!$AX$2:$AX$47,"WON")+COUNTIF(Predictions!$AX$2:$AX$47,"LOST"))) | C26: Over one weekend this is NOISE. A few hundred bets before it means anything.

Sheet Read me
A1: HOW TO USE THIS FILE
A3: Yellow columns are yours to fill in. Everything else calculates.
A4: ACTUAL yellows -- both teams combined, YELLOW cards only.
A5: Bookmaker / Card line / Over price / Under price -- what you were offered.
A6: Give BOTH prices where you can: with only one, the margin cannot be removed and your edge looks smaller than it is.
A8: READING THE ODDS COLUMNS
A9: Every probability is also shown as FAIR DECIMAL ODDS, which is 1 / probability -- the same form a bookmaker quotes.
A10: A 50% chance is 2.00. A 67% chance is 1.50. A 25% chance is 4.00.
A11: The comparison is then direct: if the bookmaker's price is LONGER than the model's fair price, that side is value.
A12: Example: model fair under 3.5 = 2.11, bookmaker offers 2.34. 2.34 > 2.11, so the under is value.
A14: WHAT WAS PREDICTED, AND WITH WHAT
A15: Negative binomial GLM, 38 features, trained on 51,823 matches to the end of 2025/26.
... A29: These fixtures are the 2026/27 holdout. Generating predictions is not a holdout look. Scoring them is, and it will be logged.

Sheet Week 26 Sep
A1: Date | B1: Div | C1: League | D1: Home | E1: Away | F1: Referee | G1: Ref matches | H1: Ref vs avg | I1: League avg | J1: Model expects | K1: vs league avg | L1: Most likely | M1: 80% range | N1: P(0) | O1: P(1) | P1: P(2) | Q1: P(3) | R1: P(4) | S1: P(5) | T1: P(6) | U1: P(7) | V1: P(8) | W1: P(o1.5) | X1: P(o2.5) | Y1: P(o3.5) | Z1: P(o4.5) | AA1: P(o5.5) | AB1: P(o6.5) | AC1: FAIR over 1.5 | AD1: FAIR over 2.5 | AE1: FAIR over 3.5 | AF1: FAIR over 4.5 | AG1: FAIR over 5.5 | AH1: FAIR over 6.5 | AI1: FAIR under 1.5 | AJ1: FAIR under 2.5 | AK1: FAIR under 3.5 | AL1: FAIR under 4.5 | AM1: FAIR under 5.5 | AN1: FAIR under 6.5 | AO1: Bookmaker | AP1: Settles on | AQ1: Card line | AR1: Over price | AS1: Under price | AT1: Stake EUR | AU1: Model P(over) | AV1: Implied P(over) | AW1: Edge | AX1: BET? | AY1: EV EUR | AZ1: ACTUAL yellows | BA1: Won? | BB1: P/L EUR | BC1: Running P/L | BD1: Notes
A2: 2026-09-26 | B2: E2 | C2: League One | D2: Cambridge | E2: AFC Wimbledon | F2: not known | G2: 0 | I2: 3.4722222 | J2: 3.2893252 | K2: -0.052674352 | L2: 3 | M2: 1-5 | N2: 0.04153661 | O2: 0.12783823 | P2: 0.2008373 | Q2: 0.21465379 | R2: 0.17551774 | S2: 0.11707183 | T2: 0.066328452 | U2: 0.032820282 | V2: 0.014473873 | W2: 0.83062516 | X2: 0.62978786 | Y2: 0.41513407 | Z2: 0.23961633 | AA2: 0.1225445 | AB2: 0.056216051 | AC2: 1.2039125 | AD2: 1.5878363 | AE2: 2.4088604 | AF2: 4.1733383 | AG2: 8.1603007 | AH2: 17.788514 | AI2: 5.9040646 | AJ2: 2.701154 | AK2: 1.7097936 | AL2: 1.3151256 | AM2: 1.1396589 | AN2: 1.0595645 | AT2: 100 | AU2: =IFERROR(IF($AQ2="","",INDEX($W2:$AB2,$AQ2-0.5)),"") | AV2: =IF($AR2="","",IF($AS2="",1/$AR2,(1/$AR2)/((1/$AR2)+(1/$AS2)))) | AW2: =IF(OR($AU2="",$AV2=""),"",$AU2-$AV2) | AX2: =IF($AW2="","",IF($AP2="","units?",IF(ISNUMBER(SEARCH("yellow",$AP2)),IF($AW2>=0.05,"OVER",IF($AW2<=-0.05,"UNDER","skip")),"UNITS?"))) | AY2: =IF(OR($AX2="",$AX2="skip",$AX2="units?",$AX2="UNITS?"),"",IF($AX2="OVER",$AT2*($AU2*$AR2-1),$AT2*((1-$AU2)*$AS2-1))) | BA2: =IF(OR($AX2="",$AX2="skip",$AX2="units?",$AX2="UNITS?",$AZ2="",$AQ2=""),"",IF($AX2="OVER",IF($AZ2>$AQ2,"WON","LOST"),IF($AZ2<$AQ2,"WON","LOST"))) | BB2: =IF($BA2="","",IF($BA2="WON",IF($AX2="OVER",$AT2*($AR2-1),$AT2*($AS2-1)),-$AT2)) | BC2: =IF(COUNT($BB$2:$BB2)=0,"",SUM($BB$2:$BB2))
A3: 2026-09-26 | B3: E2 | C3: League One | D3: Plymouth | E3: Burton | F3: not known | G3: 0 | I3: 3.4722222 | J3: 3.890149 | K3: 0.12036292 | L3: 3 | M3: 1-6 | N3: 0.023752299 | O3: 0.085451839 | P3: 0.15692462 | Q3: 0.19605204 | R3: 0.18738718 | S3: 0.14610239 | T3: 0.096758883 | U3: 0.055965368 | V3: 0.028850137 | W3: 0.89079586 | X3: 0.73387124 | Y3: 0.5378192 | Z3: 0.35043202 | AA3: 0.20432964 | AB3: 0.10757075 | AC3: 1.1225917 | AD3: 1.3626369 | AE3: 1.8593609 | AF3: 2.8536205 | AG3: 4.8940527 | AH3: 9.296207 | AI3: 9.1571622 | AJ3: 3.7575796 | AK3: 2.1636554 | AL3: 1.5394848 | AM3: 1.2568019 | AN3: 1.120537 | AT3: 100 | AU3: =IFERROR(IF($AQ3="","",INDEX($W3:$AB3,$AQ3-0.5)),"") | AV3: =IF($AR3="","",IF($AS3="",1/$AR3,(1/$AR3)/((1/$AR3)+(1/$AS3)))) | AW3: =IF(OR($AU3="",$AV3=""),"",$AU3-$AV3) | AX3: =IF($AW3="","",IF($AP3="","units?",IF(ISNUMBER(SEARCH("yellow",$AP3)),IF($AW3>=0.05,"OVER",IF($AW3<=-0.05,"UNDER","skip")),"UNITS?"))) | AY3: =IF(OR($AX3="",$AX3="skip",$AX3="units?",$AX3="UNITS?"),"",IF($AX3="OVER",$AT3*($AU3*$AR3-1),$AT3*((1-$AU3)*$AS3-1))) | BA3: =IF(OR($AX3="",$AX3="skip",$AX3="units?",$AX3="UNITS?",$AZ3="",$AQ3=""),"",IF($AX3="OVER",IF($AZ3>$AQ3,"WON","LOST"),IF($AZ3<$AQ3,"WON","LOST"))) | BB3: =IF($BA3="","",IF($BA3="WON",IF($AX3="OVER",$AT3*($AR3-1),$AT3*($AS3-1)),-$AT3)) | BC3: =IF(COUNT($BB$2:$BB3)=0,"",SUM($BB$2:$BB3))
A4: 2026-09-26 | B4: E2 | C4: League One | D4: Stockport | E4: Peterboro | F4: not known | G4: 0 | I4: 3.4722222 | J4: 3.0985767 | K4: -0.1076099 | L4: 3 | M4: 1-5 | N4: 0.049669278 | O4: 0.1445427 | P4: 0.21471302 | Q4: 0.21698574 | R4: 0.16776148 | S4: 0.10580403 | T4: 0.056679799 | U4: 0.026518525 | V4: 0.011057843 | W4: 0.80578802 | X4: 0.591075 | Y4: 0.37408927 | Z4: 0.20632779 | AA4: 0.10052376 | AB4: 0.043843959 | AC4: 1.2410212 | AD4: 1.6918327 | AE4: 2.6731588 | AF4: 4.8466568 | AG4: 9.9478971 | AH4: 22.808159 | AI4: 5.1490131 | AJ4: 2.4454362 | AK4: 1.5976719 | AL4: 1.259966 | AM4: 1.1117581 | AN4: 1.0458544 | AT4: 100 | AU4: =IFERROR(IF($AQ4="","",INDEX($W4:$AB4,$AQ4-0.5)),"") | AV4: =IF($AR4="","",IF($AS4="",1/$AR4,(1/$AR4)/((1/$AR4)+(1/$AS4)))) | AW4: =IF(OR($AU4="",$AV4=""),"",$AU4-$AV4) | AX4: =IF($AW4="","",IF($AP4="","units?",IF(ISNUMBER(SEARCH("yellow",$AP4)),IF($AW4>=0.05,"OVER",IF($AW4<=-0.05,"UNDER","skip")),"UNITS?"))) | AY4: =IF(OR($AX4="",$AX4="skip",$AX4="units?",$AX4="UNITS?"),"",IF($AX4="OVER",$AT4*($AU4*$AR4-1),$AT4*((1-$AU4)*$AS4-1))) | BA4: =IF(OR($AX4="",$AX4="skip",$AX4="units?",$AX4="UNITS?",$AZ4="",$AQ4=""),"",IF($AX4="OVER",IF($AZ4>$AQ4,"WON","LOST"),IF($AZ4<$AQ4,"WON","LOST"))) | BB4: =IF($BA4="","",IF($BA4="WON",IF($AX4="OVER",$AT4*($AR4-1),$AT4*($AS4-1)),-$AT4)) | BC4: =IF(COUNT($BB$2:$BB4)=0,"",SUM($BB$2:$BB4))
A5: 2026-09-26 | B5: E2 | C5: League One | D5: Wycombe | E5: Reading | F5: not known | G5: 0 | I5: 3.4722222 | J5: 3.4427159 | K5: -0.0084978248 | L5: 3 | M5: 1-5 | N5: 0.035990928 | O5: 0.11558893 | P5: 0.18949308 | Q5: 0.21133968 | R5: 0.18032544 | S5: 0.12551102 | T5: 0.074203234 | U5: 0.038314114 | V5: 0.017631722 | W5: 0.84842014 | X5: 0.65892706 | Y5: 0.44758738 | Z5: 0.26726194 | AA5: 0.14175092 | AB5: 0.067547686 | AC5: 1.1786613 | AD5: 1.5176187 | AE5: 2.2342006 | AF5: 3.7416476 | AG5: 7.0546279 | AH5: 14.804356 | AI5: 6.5971826 | AJ5: 2.9319242 | AK5: 1.810241 | AL5: 1.3647442 | AM5: 1.1651629 | AN5: 1.0724409 | AT5: 100 | AU5: =IFERROR(IF($AQ5="","",INDEX($W5:$AB5,$AQ5-0.5)),"") | AV5: =IF($AR5="","",IF($AS5="",1/$AR5,(1/$AR5)/((1/$AR5)+(1/$AS5)))) | AW5: =IF(OR($AU5="",$AV5=""),"",$AU5-$AV5) | AX5: =IF($AW5="","",IF($AP5="","units?",IF(ISNUMBER(SEARCH("yellow",$AP5)),IF($AW5>=0.05,"OVER",IF($AW5<=-0.05,"UNDER","skip")),"UNITS?"))) | AY5: =IF(OR($AX5="",$AX5="skip",$AX5="units?",$AX5="UNITS?"),"",IF($AX5="OVER",$AT5*($AU5*$AR5-1),$AT5*((1-$AU5)*$AS5-1))) | BA5: =IF(OR($AX5="",$AX5="skip",$AX5="units?",$AX5="UNITS?",$AZ5="",$AQ5=""),"",IF($AX5="OVER",IF($AZ5>$AQ5,"WON","LOST"),IF($AZ5<$AQ5,"WON","LOST"))) | BB5: =IF($BA5="","",IF($BA5="WON",IF($AX5="OVER",$AT5*($AR5-1),$AT5*($AS5-1)),-$AT5)) | BC5: =IF(COUNT($BB$2:$BB5)=0,"",SUM($BB$2:$BB5))
A6: 2026-09-26 | B6: E3 | C6: League Two | D6: Bristol Rvs | E6: Exeter | F6: not known | G6: 0 | I6: 3.9444444 | J6: 4.1324776 | K6: 0.047670381 | L6: 4 | M6: 1-6 | N6: 0.018993489 | O6: 0.07224956 | P6: 0.1402877 | Q6: 0.18531669 | R6: 0.18728274 | S6: 0.15439381 | T6: 0.10811305 | U6: 0.066118248 | V6: 0.036038321 | W6: 0.90875695 | X6: 0.76846925 | Y6: 0.58315256 | Z6: 0.39586982 | AA6: 0.24147601 | AB6: 0.13336296 | AC6: 1.1004042 | AD6: 1.3012882 | AE6: 1.7148171 | AF6: 2.5260829 | AG6: 4.1411982 | AH6: 7.4983341 | AI6: 10.959739 | AJ6: 4.3190808 | AK6: 2.3989592 | AL6: 1.6552724 | AM6: 1.3183499 | AN6: 1.1538856 | AT6: 100 | AU6: =IFERROR(IF($AQ6="","",INDEX($W6:$AB6,$AQ6-0.5)),"") | AV6: =IF($AR6="","",IF($AS6="",1/$AR6,(1/$AR6)/((1/$AR6)+(1/$AS6)))) | AW6: =IF(OR($AU6="",$AV6=""),"",$AU6-$AV6) | AX6: =IF($AW6="","",IF($AP6="","units?",IF(ISNUMBER(SEARCH("yellow",$AP6)),IF($AW6>=0.05,"OVER",IF($AW6<=-0.05,"UNDER","skip")),"UNITS?"))) | AY6: =IF(OR($AX6="",$AX6="skip",$AX6="units?",$AX6="UNITS?"),"",IF($AX6="OVER",$AT6*($AU6*$AR6-1),$AT6*((1-$AU6)*$AS6-1))) | BA6: =IF(OR($AX6="",$AX6="skip",$AX6="units?",$AX6="UNITS?",$AZ6="",$AQ6=""),"",IF($AX6="OVER",IF($AZ6>$AQ6,"WON","LOST"),IF($AZ6<$AQ6,"WON","LOST"))) | BB6: =IF($BA6="","",IF($BA6="WON",IF($AX6="OVER",$AT6*($AR6-1),$AT6*($AS6-1)),-$AT6)) | BC6: =IF(COUNT($BB$2:$BB6)=0,"",SUM($BB$2:$BB6))
A7: 2026-09-26 | B7: E3 | C7: League Two | D7: Cheltenham | E7: Chesterfield | F7: not known | G7: 0 | I7: 3.9444444 | J7: 3.7433164 | K7: -0.050990202 | L7: 3 | M7: 0-5 | N7: 0.027212154 | O7: 0.09447206 | P7: 0.16741631 | Q7: 0.2018379 | R7: 0.1861641 | S7: 0.14006772 | T7: 0.089515099 | U7: 0.049963115 | V7: 0.024854368 | W7: 0.87831579 | X7: 0.71089948 | Y7: 0.50906157 | Z7: 0.32289748 | AA7: 0.18282975 | AB7: 0.093314655 | AC7: 1.1385427 | AD7: 1.4066686 | AE7: 1.9643989 | AF7: 3.0969582 | AG7: 5.4695693 | AH7: 10.71643 | AI7: 8.2179928 | AJ7: 3.4590044 | AK7: 2.0369153 | AL7: 1.4768812 | AM7: 1.2237352 | AN7: 1.1029185 | AT7: 100 | AU7: =IFERROR(IF($AQ7="","",INDEX($W7:$AB7,$AQ7-0.5)),"") | AV7: =IF($AR7="","",IF($AS7="",1/$AR7,(1/$AR7)/((1/$AR7)+(1/$AS7)))) | AW7: =IF(OR($AU7="",$AV7=""),"",$AU7-$AV7) | AX7: =IF($AW7="","",IF($AP7="","units?",IF(ISNUMBER(SEARCH("yellow",$AP7)),IF($AW7>=0.05,"OVER",IF($AW7<=-0.05,"UNDER","skip")),"UNITS?"))) | AY7: =IF(OR($AX7="",$AX7="skip",$AX7="units?",$AX7="UNITS?"),"",IF($AX7="OVER",$AT7*($AU7*$AR7-1),$AT7*((1-$AU7)*$AS7-1))) | BA7: =IF(OR($AX7="",$AX7="skip",$AX7="units?",$AX7="UNITS?",$AZ7="",$AQ7=""),"",IF($AX7="OVER",IF($AZ7>$AQ7,"WON","LOST"),IF($AZ7<$AQ7,"WON","LOST"))) | BB7: =IF($BA7="","",IF($BA7="WON",IF($AX7="OVER",$AT7*($AR7-1),$AT7*($AS7-1)),-$AT7)) | BC7: =IF(COUNT($BB$2:$BB7)=0,"",SUM($BB$2:$BB7))
A8: 2026-09-26 | B8: E3 | C8: League Two | D8: Fleetwood Town | E8: Rochdale | F8: not known | G8: 0 | I8: 3.9444444 | J8: 3.8038636 | K8: -0.035640225 | L8: 3 | M8: 0-5 | N8: 0.025727053 | O8: 0.090654517 | P8: 0.16305825 | Q8: 0.19952931 | R8: 0.18679225 | S8: 0.14264612 | T8: 0.092528845 | U8: 0.05241907 | V8: 0.026466803 | W8: 0.88361843 | X8: 0.72056018 | Y8: 0.52103087 | Z8: 0.33423861 | AA8: 0.1915925 | AB8: 0.09906365 | AC8: 1.1317102 | AD8: 1.3878091 | AE8: 1.9192721 | AF8: 2.9918745 | AG8: 5.2194111 | AH8: 10.09452 | AI8: 8.5924258 | AJ8: 3.578588 | AK8: 2.0878172 | AL8: 1.5020397 | AM8: 1.2369999 | AN8: 1.1099563 | AT8: 100 | AU8: =IFERROR(IF($AQ8="","",INDEX($W8:$AB8,$AQ8-0.5)),"") | AV8: =IF($AR8="","",IF($AS8="",1/$AR8,(1/$AR8)/((1/$AR8)+(1/$AS8)))) | AW8: =IF(OR($AU8="",$AV8=""),"",$AU8-$AV8) | AX8: =IF($AW8="","",IF($AP8="","units?",IF(ISNUMBER(SEARCH("yellow",$AP8)),IF($AW8>=0.05,"OVER",IF($AW8<=-0.05,"UNDER","skip")),"UNITS?"))) | AY8: =IF(OR($AX8="",$AX8="skip",$AX8="units?",$AX8="UNITS?"),"",IF($AX8="OVER",$AT8*($AU8*$AR8-1),$AT8*((1-$AU8)*$AS8-1))) | BA8: =IF(OR($AX8="",$AX8="skip",$AX8="units?",$AX8="UNITS?",$AZ8="",$AQ8=""),"",IF($AX8="OVER",IF($AZ8>$AQ8,"WON","LOST"),IF($AZ8<$AQ8,"WON","LOST"))) | BB8: =IF($BA8="","",IF($BA8="WON",IF($AX8="OVER",$AT8*($AR8-1),$AT8*($AS8-1)),-$AT8)) | BC8: =IF(COUNT($BB$2:$BB8)=0,"",SUM($BB$2:$BB8))
A9: 2026-09-26 | B9: E3 | C9: League Two | D9: Newport County | E9: Grimsby | F9: not known | G9: 0 | I9: 3.9444444 | J9: 3.9510107 | K9: 0.0016646849 | L9: 3 | M9: 1-6 | N9: 0.022453069 | O9: 0.081945067 | P9: 0.1526595 | Q9: 0.19347972 | R9: 0.18760106 | S9: 0.14838297 | T9: 0.099689391 | U9: 0.058493661 | V9: 0.030589238 | W9: 0.89560186 | X9: 0.74294236 | Y9: 0.54946265 | Z9: 0.36186158 | AA9: 0.21347861 | AB9: 0.11378922 | AC9: 1.1165676 | AD9: 1.3459994 | AE9: 1.8199599 | AF9: 2.7634876 | AG9: 4.6843101 | AH9: 8.7881788 | AI9: 9.578715 | AJ9: 3.8901781 | AK9: 2.2195718 | AL9: 1.5670581 | AM9: 1.2714212 | AN9: 1.1283997 | AT9: 100 | AU9: =IFERROR(IF($AQ9="","",INDEX($W9:$AB9,$AQ9-0.5)),"") | AV9: =IF($AR9="","",IF($AS9="",1/$AR9,(1/$AR9)/((1/$AR9)+(1/$AS9)))) | AW9: =IF(OR($AU9="",$AV9=""),"",$AU9-$AV9) | AX9: =IF($AW9="","",IF($AP9="","units?",IF(ISNUMBER(SEARCH("yellow",$AP9)),IF($AW9>=0.05,"OVER",IF($AW9<=-0.05,"UNDER","skip")),"UNITS?"))) | AY9: =IF(OR($AX9="",$AX9="skip",$AX9="units?",$AX9="UNITS?"),"",IF($AX9="OVER",$AT9*($AU9*$AR9-1),$AT9*((1-$AU9)*$AS9-1))) | BA9: =IF(OR($AX9="",$AX9="skip",$AX9="units?",$AX9="UNITS?",$AZ9="",$AQ9=""),"",IF($AX9="OVER",IF($AZ9>$AQ9,"WON","LOST"),IF($AZ9<$AQ9,"WON","LOST"))) | BB9: =IF($BA9="","",IF($BA9="WON",IF($AX9="OVER",$AT9*($AR9-1),$AT9*($AS9-1)),-$AT9)) | BC9: =IF(COUNT($BB$2:$BB9)=0,"",SUM($BB$2:$BB9))
A10: 2026-09-26 | B10: E3 | C10: League Two | D10: Oldham | E10: Salford | F10: not known | G10: 0 | I10: 3.9444444 | J10: 3.9888927 | K10: 0.011268561 | L10: 3 | M10: 1-6 | N10: 0.021681252 | O10: 0.079828518 | P10: 0.15003263 | Q10: 0.19183327 | R10: 0.18765079 | S10: 0.14973585 | T10: 0.10148861 | U10: 0.060076381 | V10: 0.031694962 | W10: 0.89849023 | X10: 0.7484576 | Y10: 0.55662433 | Z10: 0.36897354 | AA10: 0.21923769 | AB10: 0.11774908 | AC10: 1.1129782 | AD10: 1.336081 | AE10: 1.7965438 | AF10: 2.7102214 | AG10: 4.5612595 | AH10: 8.492635 | AI10: 9.8512685 | AJ10: 3.975473 | AK10: 2.2554237 | AL10: 1.5847196 | AM10: 1.2807995 | AN10: 1.1334644 | AT10: 100 | AU10: =IFERROR(IF($AQ10="","",INDEX($W10:$AB10,$AQ10-0.5)),"") | AV10: =IF($AR10="","",IF($AS10="",1/$AR10,(1/$AR10)/((1/$AR10)+(1/$AS10)))) | AW10: =IF(OR($AU10="",$AV10=""),"",$AU10-$AV10) | AX10: =IF($AW10="","",IF($AP10="","units?",IF(ISNUMBER(SEARCH("yellow",$AP10)),IF($AW10>=0.05,"OVER",IF($AW10<=-0.05,"UNDER","skip")),"UNITS?"))) | AY10: =IF(OR($AX10="",$AX10="skip",$AX10="units?",$AX10="UNITS?"),"",IF($AX10="OVER",$AT10*($AU10*$AR10-1),$AT10*((1-$AU10)*$AS10-1))) | BA10: =IF(OR($AX10="",$AX10="skip",$AX10="units?",$AX10="UNITS?",$AZ10="",$AQ10=""),"",IF($AX10="OVER",IF($AZ10>$AQ10,"WON","LOST"),IF($AZ10<$AQ10,"WON","LOST"))) | BB10: =IF($BA10="","",IF($BA10="WON",IF($AX10="OVER",$AT10*($AR10-1),$AT10*($AS10-1)),-$AT10)) | BC10: =IF(COUNT($BB$2:$BB10)=0,"",SUM($BB$2:$BB10))
